Workbook

Sheet B_DENS
A1: Treatment | B1: Distance TIM | C1: Lower_CI | D1: Upper_CI | E1: Treatment | F1: Distance MD | G1: Lower_CI | H1: Upper_CI | I1: Treatment | J1: Distance totale | K1: Lower_CI | L1: Upper_CI
A2: 0.032 | B2: 10.930821 | C2: 16.967443 | D2: 4.8941986 | E2: 0.025 | F2: 0.91223773 | G2: 1.8245271 | H2: -5.16021e-05 | I2: 0.03 | J2: 18.82056 | K2: 26.13549 | L2: 11.50563 | N2: =MIN(J:J) -> 10.401756
A3: 0.041 | B3: 10.542811 | C3: 15.986489 | D3: 5.0991337 | E3: 0.034 | F3: 0.96605714 | G3: 1.8233511 | H3: 0.10876316 | I3: 0.039 | J3: 18.30104 | K3: 24.68677 | L3: 11.91531 | N3: =MAX(J:J) -> 18.82056
A4: 0.046 | B4: 10.332385 | C4: 15.602733 | D4: 5.0620373 | E4: 0.043 | F4: 1.0185844 | G4: 1.8495869 | H4: 0.18758192 | I4: 0.043 | J4: 18.075452 | K4: 24.356311 | L4: 11.794593
A5: 0.055 | B5: 9.9628611 | C5: 14.834657 | D5: 5.091065 | E5: 0.048 | F5: 1.0472079 | G5: 1.8651522 | H5: 0.22926355 | I5: 0.05 | J5: 17.688535 | K5: 23.603417 | L5: 11.773654
A6: 0.064 | B6: 9.6052204 | C6: 14.060704 | D6: 5.1497365 | E6: 0.053 | F6: 1.0754325 | G6: 1.9054267 | H6: 0.24543837 | I6: 0.057 | J6: 17.311626 | K6: 22.940218 | L6: 11.683034
A7: 0.069 | B7: 9.4116658 | C7: 13.638727 | D7: 5.1846043 | E7: 0.062 | F7: 1.1252319 | G7: 1.9501202 | H7: 0.30034355 | I7: 0.066 | J7: 16.841732 | K7: 22.039012 | L7: 11.644452
A8: 0.074 | B8: 9.221779 | C8: 13.313758 | D8: 5.1297999 | E8: 0.066 | F8: 1.1469502 | G8: 1.9451484 | H8: 0.34875193 | I8: 0.075 | J8: 16.38838 | K8: 21.296978 | L8: 11.479782
A9: 0.078 | B9: 9.0725103 | C9: 13.093199 | D9: 5.0518212 | E9: 0.072 | F9: 1.179049 | G9: 1.9812328 | H9: 0.37686524 | I9: 0.08 | J9: 16.143666 | K9: 20.962601 | L9: 11.32473
A10: 0.083 | B10: 8.8892253 | C10: 12.742516 | D10: 5.0359342 | E10: 0.076 | F10: 1.2001292 | G10: 2.0108949 | H10: 0.38936358 | I10: 0.085 | J10: 15.904057 | K10: 20.471867 | L10: 11.336247
A11: 0.088 | B11: 8.7096081 | C11: 12.441785 | D11: 4.9774313 | E11: 0.08 | F11: 1.2209542 | G11: 2.0123275 | H11: 0.42958086 | I11: 0.089 | J11: 15.716046 | K11: 20.165701 | L11: 11.266391
A12: 0.091 | B12: 8.6035982 | C12: 12.288909 | D12: 4.9182874 | E12: 0.085 | F12: 1.2466264 | G12: 2.0388193 | H12: 0.4544336 | I12: 0.098 | J12: 15.304969 | K12: 19.515457 | L12: 11.09448
A13: 0.097 | B13: 8.3955396 | C13: 11.91393 | D13: 4.8771489 | E13: 0.09 | F13: 1.2718999 | G13: 2.0837085 | H13: 0.46009122 | I13: 0.103 | J13: 15.08374 | K13: 19.071041 | L13: 11.096439
A14: 0.1 | B14: 8.2934908 | C14: 11.693681 | D14: 4.8933004 | E14: 0.099 | F14: 1.3163871 | G14: 2.0975416 | H14: 0.53523254 | I14: 0.108 | J14: 14.867617 | K14: 18.690926 | L14: 11.044308
A15: 0.102 | B15: 8.2261919 | C15: 11.524203 | D15: 4.9281804 | E15: 0.104 | F15: 1.3405438 | G15: 2.1212297 | H15: 0.55985799 | I15: 0.112 | J15: 14.698395 | K15: 18.475648 | L15: 10.921142
... A59: 0.354 | B59: 4.4417696 | C59: 7.8460187 | D59: 1.0375206 | E59: 0.376 | F59: 2.0537087 | G59: 3.5075805 | H59: 0.59983688 | I59: 0.428 | J59: 11.655405 | K59: 16.288241 | L59: 7.0225686
A60: 0.378 | B60: 4.5672457 | C60: 8.5671229 | D60: 0.56736848 | E60: 0.396 | F60: 2.059566 | G60: 3.2273559 | H60: 0.89177597
A61: 0.396 | B61: 4.7168084 | C61: 8.3698637 | D61: 1.0637531 | E61: 0.404 | F61: 2.0601222 | G61: 3.100529 | H61: 1.0197153
A62: 0.405 | B62: 4.8094148 | C62: 8.1643028 | D62: 1.4545268 | E62: 0.412 | F62: 2.0596574 | G62: 3.0231275 | H62: 1.0961874
A63: 0.41 | B63: 4.8659976 | C63: 8.1168733 | D63: 1.6151219 | E63: 0.418 | F63: 2.0586389 | G63: 2.9599405 | H63: 1.1573372
A64: 0.418 | B64: 4.9641589 | C64: 8.1040988 | D64: 1.8242189 | E64: 0.421 | F64: 2.0579142 | G64: 2.9367218 | H64: 1.1791067
A65: 0.428 | B65: 5.1000642 | C65: 8.5307152 | D65: 1.6694132 | E65: 0.428 | F65: 2.0556651 | G65: 2.9600214 | H65: 1.1513087

Sheet B15BTOT
A1: Treatment | B1: Distance TIM | C1: Lower_CI | D1: Upper_CI | E1: Treatment | F1: Distance MD | G1: Lower_CI | H1: Upper_CI | I1: Treatment | J1: Distance totale | K1: Lower_CI | L1: Upper_CI
A2: 10.285 | B2: 6.135976 | C2: 9.134192 | D2: 3.13776 | E2: 8.13 | F2: 1.0561498 | G2: 1.8177131 | H2: 0.29458653 | I2: 8.13 | J2: 12.703412 | K2: 16.855482 | L2: 8.5513424 | N2: =MIN(J:J) -> 6.1546025
A3: 11.55 | B3: 6.1242194 | C3: 9.1245954 | D3: 3.1238435 | E3: 11.55 | F3: 1.084239 | G3: 1.8503652 | H3: 0.3181128 | I3: 11.55 | J3: 12.663307 | K3: 16.780567 | L3: 8.5460472 | N3: =MAX(J:J) -> 12.703412
A4: 14.97 | B4: 6.0921774 | C4: 9.2143826 | D4: 2.9699721 | E4: 14.97 | F4: 1.1118794 | G4: 1.9067924 | H4: 0.31696652 | I4: 14.97 | J4: 12.622651 | K4: 16.925098 | L4: 8.3202041
A5: 18.39 | B5: 6.0597593 | C5: 9.2179028 | D5: 2.9016158 | E5: 18.39 | F5: 1.1390712 | G5: 1.9382162 | H5: 0.33992607 | I5: 18.39 | J5: 12.581444 | K5: 16.894586 | L5: 8.2683026
A6: 21.81 | B6: 6.0269653 | C6: 9.1055472 | D6: 2.9483833 | E6: 21.631 | F6: 1.1644256 | G6: 1.9499165 | H6: 0.37893458 | I6: 21.81 | J6: 12.539686 | K6: 16.731848 | L6: 8.3475244
A7: 25.23 | B7: 5.9937953 | C7: 8.9929086 | D7: 2.9946819 | E7: 21.81 | F7: 1.1658141 | G7: 1.9519277 | H7: 0.37970053 | I7: 25.23 | J7: 12.497377 | K7: 16.524276 | L7: 8.4704787
A8: 28.65 | B8: 5.9602493 | C8: 8.9383364 | D8: 2.9821623 | E8: 25.23 | F8: 1.1921084 | G8: 1.9729064 | H8: 0.41131037 | I8: 28.65 | J8: 12.454518 | K8: 16.493325 | L8: 8.4157107
A9: 32.07 | B9: 5.9263274 | C9: 8.8251667 | D9: 3.0274881 | E9: 28.65 | F9: 1.2179539 | G9: 2.0015405 | H9: 0.43436724 | I9: 34.863 | J9: 12.375246 | K9: 16.080263 | L9: 8.6702296
A10: 35.49 | B10: 5.8920295 | C10: 8.6528495 | D10: 3.1312095 | E10: 32.07 | F10: 1.2433506 | G10: 2.002885 | H10: 0.48381623 | I10: 35.49 | J10: 12.367145 | K10: 16.029753 | L10: 8.7045379
A11: 38.91 | B11: 5.8573556 | C11: 8.4797044 | D11: 3.2350069 | E11: 35.49 | F11: 1.2682986 | G11: 2.0026931 | H11: 0.53390422 | I11: 38.91 | J11: 12.322633 | K11: 15.863297 | L11: 8.7819685
A12: 42.33 | B12: 5.8223058 | C12: 8.3943483 | D12: 3.2502633 | E12: 38.91 | F12: 1.2927979 | G12: 2.0009771 | H12: 0.5846187 | I12: 42.33 | J12: 12.277569 | K12: 15.740904 | L12: 8.8142348
A13: 45.75 | B13: 5.78688 | C13: 8.219637 | D13: 3.354123 | E13: 42.33 | F13: 1.3168485 | G13: 2.0253539 | H13: 0.60834305 | I13: 45.75 | J13: 12.231955 | K13: 15.527573 | L13: 8.9363371
A14: 52.59 | B14: 5.7149004 | C14: 8.0762682 | D14: 3.3535327 | E14: 45.75 | F14: 1.3404503 | G14: 2.0209909 | H14: 0.65990966 | I14: 52.554 | J14: 12.139568 | K14: 15.324526 | L14: 8.9546107
A15: 56.01 | B15: 5.6783467 | C15: 7.9890885 | D15: 3.3676049 | E15: 49.17 | F15: 1.3636033 | G15: 2.0340234 | H15: 0.69318326 | I15: 52.59 | J15: 12.139074 | K15: 15.324168 | L15: 8.9539796
... A69: 339.87 | B69: 1.3337535 | C69: 4.0249948 | D69: -1.3574878 | E69: 339.87 | F69: 1.6914729 | G69: 2.3945934 | H69: 0.98835231 | I69: 343.29 | J69: 6.1546025 | K69: 10.394085 | L69: 1.9151205
A70: 343.29 | B70: 1.2656182 | C70: 4.3214922 | D70: -1.7902558 | E70: 343.29 | F70: 1.6760344 | G70: 2.4613965 | H70: 0.89067225

Sheet ENTROPY
A1: Treatment | B1: Distance TIM | C1: Lower_CI | D1: Upper_CI | E1: Treatment | F1: Distance MD | G1: Lower_CI | H1: Upper_CI | I1: Treatment | J1: Distance totale | K1: Lower_CI | L1: Upper_CI
A2: 0.42 | B2: 8.4000226 | C2: 13.185637 | D2: 3.6144086 | E2: 0.398 | F2: 1.7898566 | G2: 2.9718662 | H2: 0.6078469 | I2: 0.399 | J2: 17.93295 | K2: 24.357732 | L2: 11.508168 | N2: =MIN(J:J) -> 11.255459
A3: 0.461 | B3: 7.6285726 | C3: 12.779904 | D3: 2.477241 | E3: 0.44 | F3: 1.792781 | G3: 3.0374707 | H3: 0.54809134 | I3: 0.448 | J3: 16.547089 | K3: 23.392716 | L3: 9.7014625 | N3: =MAX(J:J) -> 17.93295
A4: 0.508 | B4: 6.8643779 | C4: 10.889563 | D4: 2.8391924 | E4: 0.484 | F4: 1.7967654 | G4: 2.9279359 | H4: 0.66559487 | I4: 0.49 | J4: 15.487324 | K4: 21.333219 | L4: 9.6414299
A5: 0.529 | B5: 6.5644123 | C5: 10.241073 | D5: 2.8877514 | E5: 0.512 | F5: 1.7997914 | G5: 2.8089805 | H5: 0.79060236 | I5: 0.518 | J5: 14.846514 | K5: 20.047916 | L5: 9.6451122
A6: 0.55 | B6: 6.2900688 | C6: 9.6649452 | D6: 2.9151924 | E6: 0.546 | F6: 1.8039788 | G6: 2.685821 | H6: 0.92213663 | I6: 0.548 | J6: 14.218258 | K6: 18.73635 | L6: 9.7001657
A7: 0.563 | B7: 6.1330772 | C7: 9.2223186 | D7: 3.0438358 | E7: 0.548 | F7: 1.8042427 | G7: 2.6687445 | H7: 0.93974079 | I7: 0.562 | J7: 13.94572 | K7: 18.121154 | L7: 9.7702856
A8: 0.569 | B8: 6.0639312 | C8: 9.0741867 | D8: 3.0536757 | E8: 0.562 | F8: 1.806144 | G8: 2.6069963 | H8: 1.0052917 | I8: 0.568 | J8: 13.83294 | K8: 17.880425 | L8: 9.7854563
A9: 0.576 | B9: 5.9859044 | C9: 8.884501 | D9: 3.0873077 | E9: 0.568 | F9: 1.8069881 | G9: 2.5840148 | H9: 1.0299613 | I9: 0.582 | J9: 13.579174 | K9: 17.429338 | L9: 9.7290098
A10: 0.59 | B10: 5.8383914 | C10: 8.6867584 | D10: 2.9900245 | E10: 0.582 | F10: 1.8090257 | G10: 2.5598349 | H10: 1.0582164 | I10: 0.589 | J10: 13.457218 | K10: 17.122262 | L10: 9.7921751
A11: 0.597 | B11: 5.7689053 | C11: 8.5365249 | D11: 3.0012857 | E11: 0.589 | F11: 1.8100802 | G11: 2.5261684 | H11: 1.093992 | I11: 0.595 | J11: 13.3553 | K11: 16.994631 | L11: 9.715968
A12: 0.61 | B12: 5.6474126 | C12: 8.2072652 | D12: 3.0875599 | E12: 0.596 | F12: 1.8111586 | G12: 2.5236426 | H12: 1.0986747 | I12: 0.596 | J12: 13.338548 | K12: 17.038949 | L12: 9.6381466
A13: 0.617 | B13: 5.5860604 | C13: 8.1343175 | D13: 3.0378033 | E13: 0.611 | F13: 1.8135498 | G13: 2.4975764 | H13: 1.1295233 | I13: 0.611 | J13: 13.095315 | K13: 16.586871 | L13: 9.6037598
A14: 0.631 | B14: 5.4718967 | C14: 7.8809841 | D14: 3.0628094 | E14: 0.618 | F14: 1.8147032 | G14: 2.4724689 | H14: 1.1569375 | I14: 0.618 | J14: 12.986969 | K14: 16.396974 | L14: 9.5769643
A15: 0.638 | B15: 5.4190852 | C15: 7.9300052 | D15: 2.9081653 | E15: 0.633 | F15: 1.8172549 | G15: 2.4550923 | H15: 1.1794176 | I15: 0.633 | J15: 12.76586 | K15: 16.129801 | L15: 9.4019188
... A41: 0.91 | B41: 5.571518 | C41: 8.627392 | D41: 2.515644 | E41: 0.91 | F41: 1.8840576 | G41: 2.6535538 | H41: 1.1145614 | I41: 0.903 | J41: 11.365299 | K41: 15.352867 | L41: 7.3777308
I42: 0.91 | J42: 11.393984 | K42: 15.502348 | L42: 7.2856203

Sheet FEUX_R_ARE
A1: Treatment | B1: Distance TIM | C1: Lower_CI | D1: Upper_CI | E1: Treatment | F1: Distance MD | G1: Lower_CI | H1: Upper_CI | I1: Treatment | J1: Distance totale | K1: Lower_CI | L1: Upper_CI
A2: 8.118 | B2: 5.6944084 | C2: 14.804372 | D2: -3.4155556 | E2: 8.118 | F2: 1.5630773 | G2: 2.4753666 | H2: 0.65078799 | I2: 8.118 | J2: 12.258695 | K2: 19.591411 | L2: 4.9259801 | N2: =MIN(J:J) -> 8.0220463
A3: 27.06 | B3: 5.5645963 | C3: 10.865478 | D3: 0.26371418 | E3: 27.06 | F3: 1.5775838 | G3: 2.1791527 | H3: 0.97601492 | I3: 27.06 | J3: 12.077741 | K3: 16.422025 | L3: 7.7334571 | N3: =MAX(J:J) -> 12.258695
A4: 42.011 | B4: 5.4634443 | C4: 10.062761 | D4: 0.86412788 | E4: 45.1 | F4: 1.5911165 | G4: 2.1503509 | H4: 1.0318822 | I4: 45.1 | J4: 11.909071 | K4: 15.640417 | L4: 8.1777247
A5: 45.1 | B5: 5.4426894 | C5: 10.025402 | D5: 0.85997678 | E5: 63.14 | F5: 1.6043732 | G5: 2.1530308 | H5: 1.0557157 | I5: 63.14 | J5: 11.743978 | K5: 15.281398 | L5: 8.2065588
A6: 63.14 | B6: 5.3224642 | C6: 9.5932211 | D6: 1.0517072 | E6: 81.18 | F6: 1.6173539 | G6: 2.1551078 | H6: 1.0795999 | I6: 99.22 | J6: 11.424528 | K6: 14.687947 | L6: 8.1611077
A7: 81.18 | B7: 5.2039206 | C7: 9.2797454 | D7: 1.1280957 | E7: 99.22 | F7: 1.6300584 | G7: 2.1649385 | H7: 1.0951784 | I7: 117.26 | J7: 11.270169 | K7: 14.597865 | L7: 7.9424727
A8: 99.22 | B8: 5.0870586 | C8: 8.9225625 | D8: 1.2515548 | E8: 117.26 | F8: 1.642487 | G8: 2.1912176 | H8: 1.0937564 | I8: 135.3 | J8: 11.119388 | K8: 14.607877 | L8: 7.6308993
A9: 117.26 | B9: 4.9718783 | C9: 8.8292768 | D9: 1.1144799 | E9: 135.3 | F9: 1.6546394 | G9: 2.2344525 | H9: 1.0748264 | I9: 153.34 | J9: 10.972185 | K9: 14.523396 | L9: 7.4209747
A10: 135.3 | B10: 4.8583797 | C10: 8.7850841 | D10: 0.93167524 | E10: 153.34 | F10: 1.6665159 | G10: 2.2693182 | H10: 1.0637135 | I10: 171.38 | J10: 10.828561 | K10: 14.394886 | L10: 7.2622352
A11: 153.34 | B11: 4.7465627 | C11: 8.6410237 | D11: 0.85210164 | E11: 171.38 | F11: 1.6781162 | G11: 2.2955611 | H11: 1.0606714 | I11: 189.42 | J11: 10.688514 | K11: 14.459414 | L11: 6.9176137
A12: 171.38 | B12: 4.6364273 | C12: 8.5463655 | D12: 0.72648911 | E12: 189.42 | F12: 1.6894405 | G12: 2.3480527 | H12: 1.0308283 | I12: 207.46 | J12: 10.552045 | K12: 14.47863 | L12: 6.6254592
A13: 189.42 | B13: 4.5279736 | C13: 8.5449777 | D13: 0.51096946 | E13: 207.46 | F13: 1.7004888 | G13: 2.4009605 | H13: 1.0000171 | I13: 225.5 | J13: 10.419153 | K13: 14.361237 | L13: 6.4770699
A14: 207.46 | B14: 4.4212015 | C14: 8.5855703 | D14: 0.25683273 | E14: 225.5 | F14: 1.711261 | G14: 2.4274298 | H14: 0.99509212 | I14: 243.54 | J14: 10.28984 | K14: 14.294747 | L14: 6.2849332
A15: 225.5 | B15: 4.3161111 | C15: 8.4863245 | D15: 0.1458976 | E15: 243.54 | F15: 1.7217571 | G15: 2.4628432 | H15: 0.98067098 | I15: 261.58 | J15: 10.164105 | K15: 14.323983 | L15: 6.0042267
... A36: 1343.98 | B36: 1.0847562 | C36: 8.5506591 | D36: -6.3811467 | E36: 1596.54 | F36: 1.7222109 | G36: 3.0946114 | H36: 0.34981042 | I36: 1596.54 | J36: 10.788389 | K36: 19.442177 | L36: 2.1346009
A37: 1596.54 | B37: 1.2497304 | C37: 7.4191364 | D37: -4.9196756

Sheet MAX_DTV
A1: Treatment | B1: Distance TIM | C1: Lower_CI | D1: Upper_CI | E1: Treatment | F1: Distance MD | G1: Lower_CI | H1: Upper_CI | I1: Treatment | J1: Distance totale | K1: Lower_CI | L1: Upper_CI
A2: 1398.6 | B2: 7.0440844 | C2: 10.702871 | D2: 3.3852978 | E2: 1150.848 | F2: 1.4611883 | G2: 1.8657688 | H2: 1.0566078 | I2: 1398.6 | J2: 14.993366 | K2: 17.221635 | L2: 12.765098 | N2: =MIN(J:J) -> 10.612309
A3: 1798.2 | B3: 6.947252 | C3: 10.415763 | D3: 3.4787409 | E3: 1398.6 | F3: 1.4753653 | G3: 1.8438047 | H3: 1.1069258 | I3: 2197.8 | J3: 14.619131 | K3: 16.300079 | L3: 12.938182 | N3: =MAX(J:J) -> 14.993366
A4: 2197.8 | B4: 6.8527334 | C4: 10.045574 | D4: 3.6598931 | E4: 1798.2 | F4: 1.4978274 | G4: 1.8312595 | H4: 1.1643953 | I4: 2597.4 | J4: 14.438266 | K4: 15.921896 | L4: 12.954637
A5: 2597.4 | B5: 6.7605289 | C5: 9.6805487 | D5: 3.840509 | E5: 2197.8 | F5: 1.5197908 | G5: 1.8087042 | H5: 1.2308774 | I5: 2997 | J5: 14.261571 | K5: 15.781322 | L5: 12.74182
A6: 2997 | B6: 6.6706383 | C6: 9.4077695 | D6: 3.933507 | E6: 2597.4 | F6: 1.5412555 | G6: 1.8092903 | H6: 1.2732207 | I6: 3396.6 | J6: 14.089045 | K6: 15.507666 | L6: 12.670423
A7: 3396.6 | B7: 6.5830616 | C7: 9.0520372 | D7: 4.1140861 | E7: 2997 | F7: 1.5622215 | G7: 1.8511109 | H7: 1.2733321 | I7: 3796.2 | J7: 13.920687 | K7: 15.194411 | L7: 12.646963
A8: 3796.2 | B8: 6.4977989 | C8: 8.7296638 | D8: 4.265934 | E8: 3396.6 | F8: 1.5826887 | G8: 1.8584215 | H8: 1.306956 | I8: 4195.8 | J8: 13.756499 | K8: 15.02315 | L8: 12.489847
A9: 4195.8 | B9: 6.4148502 | C9: 8.4980896 | D9: 4.3316108 | E9: 3796.2 | F9: 1.6026573 | G9: 1.8559952 | H9: 1.3493194 | I9: 4595.4 | J9: 13.596479 | K9: 14.901601 | L9: 12.291357
A10: 4595.4 | B10: 6.3342154 | C10: 8.3278073 | D10: 4.3406235 | E10: 4195.8 | F10: 1.6221271 | G10: 1.870044 | H10: 1.3742103 | I10: 5394.6 | J10: 13.288947 | K10: 14.359234 | L10: 12.218659
A11: 4995 | B11: 6.2558946 | C11: 8.1030323 | D11: 4.4087569 | E11: 4228.979 | F11: 1.6237213 | G11: 1.8807764 | H11: 1.3666662 | I11: 5794.2 | J11: 13.141434 | K11: 14.340767 | L11: 11.942101
A12: 5394.6 | B12: 6.1798877 | C12: 7.8814802 | D12: 4.4782953 | E12: 4595.4 | F12: 1.6410982 | G12: 1.9102522 | H12: 1.3719443 | I12: 6193.8 | J12: 12.99809 | K12: 14.28173 | L12: 11.714451
A13: 5794.2 | B13: 6.1061949 | C13: 7.8071476 | D13: 4.4052421 | E13: 4855.423 | F13: 1.6531751 | G13: 1.9065171 | H13: 1.3998331 | I13: 6593.4 | J13: 12.858916 | K13: 14.315086 | L13: 11.402746
A14: 6193.8 | B14: 6.0348159 | C14: 7.6780689 | D14: 4.3915629 | E14: 5394.6 | F14: 1.6775443 | G14: 1.9168683 | H14: 1.4382203 | I14: 6993 | J14: 12.72391 | K14: 14.440243 | L14: 11.007577
A15: 6593.4 | B15: 5.9657509 | C15: 7.5807028 | D15: 4.3507991 | E15: 5794.2 | F15: 1.6950193 | G15: 1.9559826 | H15: 1.434056 | I15: 7392.6 | J15: 12.593073 | K15: 14.569023 | L15: 10.617124
... A50: 31768.2 | B50: 6.2795988 | C50: 10.946331 | D50: 1.6128665 | E50: 21378.6 | F50: 1.9875442 | G50: 2.9134136 | H50: 1.0616749 | I50: 36163.8 | J50: 14.128877 | K50: 19.723245 | L50: 8.5345088
A51: 36163.8 | B51: 7.2761789 | C51: 12.119451 | D51: 2.4329069 | E51: 22977 | F51: 1.9746572 | G51: 2.6655093 | H51: 1.283805
E52: 23376.6 | F52: 1.9701886 | G52: 2.7622746 | H52: 1.1781026
E53: 26573.4 | F53: 1.9164864 | G53: 3.0030311 | H53: 0.82994166
E54: 27372.6 | F54: 1.8980737 | G54: 2.6449784 | H54: 1.1511689
E55: 28571.4 | F55: 1.8667142 | G55: 2.6652812 | H55: 1.0681472
E56: 33366.6 | F56: 1.6963919 | G56: 2.5614893 | H56: 0.8312946
E57: 36163.8 | F57: 1.5638726 | G57: 2.5237597 | H57: 0.60398559

Sheet P_comb_tc
A1: Treatment | B1: Distance TIM | C1: Lower_CI | D1: Upper_CI | E1: Treatment | F1: Distance MD | G1: Lower_CI | H1: Upper_CI | I1: Treatment | J1: Distance totale | K1: Lower_CI | L1: Upper_CI
A2: 2741.208 | B2: 6.2487149 | C2: 13.011243 | D2: -0.51381341 | E2: 2741.208 | F2: 1.245839 | G2: 2.1343294 | H2: 0.35734849 | I2: 2741.208 | J2: 12.853575 | K2: 22.119247 | L2: 3.5879028 | N2: =MIN(J:J) -> 5.3654436
A3: 4143.958 | B3: 6.2294539 | C3: 12.503558 | D3: -0.044649774 | E3: 4143.958 | F3: 1.2578177 | G3: 2.0970569 | H3: 0.41857856 | I3: 4143.958 | J3: 12.776419 | K3: 21.232191 | L3: 4.3206469 | N3: =MAX(J:J) -> 12.853575
A4: 5546.71 | B4: 6.2089178 | C4: 12.387122 | D4: 0.030713394 | E4: 5546.71 | F4: 1.2698823 | G4: 2.0913245 | H4: 0.44844004 | I4: 5546.71 | J4: 12.699003 | K4: 20.711019 | L4: 4.686986
A5: 6949.46 | B5: 6.1871068 | C5: 12.267527 | D5: 0.10668661 | E5: 8352.211 | F5: 1.2942688 | G5: 2.0547254 | H5: 0.53381219 | I5: 8352.211 | J5: 12.543388 | K5: 19.715698 | L5: 5.3710785
A6: 8352.211 | B6: 6.1640209 | C6: 11.973962 | D6: 0.35407999 | E6: 9754.962 | F6: 1.3065908 | G6: 2.0481862 | H6: 0.56499537 | I6: 9754.962 | J6: 12.465191 | K6: 19.240706 | L6: 5.689675
A7: 9754.962 | B7: 6.13966 | C7: 11.7801 | D7: 0.49921947 | E7: 11157.713 | F7: 1.3189986 | G7: 2.049728 | H7: 0.58826914 | I7: 11157.713 | J7: 12.386732 | K7: 18.856378 | L7: 5.9170868
A8: 11157.713 | B8: 6.1140241 | C8: 11.568955 | D8: 0.65909328 | E8: 12560.464 | F8: 1.3314922 | G8: 2.0428007 | H8: 0.62018359 | I8: 12560.464 | J8: 12.308014 | K8: 18.48274 | L8: 6.1332872
A9: 11444.639 | B9: 6.1086234 | C9: 11.560511 | D9: 0.6567361 | E9: 13963.214 | F9: 1.3440715 | G9: 2.0272034 | H9: 0.66093966 | I9: 13963.214 | J9: 12.229034 | K9: 18.04679 | L9: 6.411279
A10: 12560.464 | B10: 6.0871133 | C10: 11.413641 | D10: 0.7605858 | E10: 15365.966 | F10: 1.3567367 | G10: 2.0452299 | H10: 0.66824354 | I10: 15365.966 | J10: 12.149795 | K10: 17.837508 | L10: 6.4620812
A11: 13963.214 | B11: 6.0589276 | C11: 11.200711 | D11: 0.91714396 | E11: 19574.219 | F11: 1.3952471 | G11: 2.0218828 | H11: 0.76861152 | I11: 19574.219 | J11: 11.910513 | K11: 16.565571 | L11: 7.2554547
A12: 15365.966 | B12: 6.0294668 | C12: 11.212378 | D12: 0.84655605 | E12: 20976.97 | F12: 1.4082555 | G12: 2.0135687 | H12: 0.80294239 | I12: 20976.97 | J12: 11.830231 | K12: 16.25449 | L12: 7.4059726
A13: 19574.219 | B13: 5.9334349 | C13: 10.453578 | D13: 1.4132916 | E13: 22379.72 | F13: 1.4213498 | G13: 2.0315053 | H13: 0.81119416 | I13: 22379.72 | J13: 11.749689 | K13: 16.015664 | L13: 7.4837152
A14: 20976.97 | B14: 5.8988743 | C14: 10.23699 | D14: 1.5607586 | E14: 23782.471 | F14: 1.4345298 | G14: 2.0317552 | H14: 0.83730429 | I14: 23782.471 | J14: 11.668887 | K14: 15.720123 | L14: 7.6176505
A15: 22379.72 | B15: 5.8630389 | C15: 10.075296 | D15: 1.6507814 | E15: 26587.973 | F15: 1.4611472 | G15: 2.0952187 | H15: 0.8270757 | I15: 25185.222 | J15: 11.587824 | K15: 15.676767 | L15: 7.4988808
... A63: 107947.52 | B63: 1.2661324 | C63: 4.6779415 | D63: -2.1456767 | E63: 121975.03 | F63: 2.570355 | G63: 3.4429796 | H63: 1.6977304 | I63: 107947.52 | J63: 6.3440766 | K63: 10.914798 | L63: 1.773355
A64: 113558.53 | B64: 0.79895185 | C64: 4.3259009 | D64: -2.7279972 | I64: 113558.53 | J64: 5.9557492 | K64: 10.674404 | L64: 1.2370942
A65: 114961.28 | B65: 0.67896919 | C65: 4.2110901 | D65: -2.8531517 | I65: 114961.28 | J65: 5.858016 | K65: 10.606314 | L65: 1.1097182
A66: 121975.03 | B66: 0.059932089 | C66: 3.4040961 | D66: -3.2842319 | I66: 121975.03 | J66: 5.3654436 | K66: 9.9108676 | L66: 0.82001963

Sheet P_comb_tim
A1: Treatment | B1: Distance TIM | C1: Lower_CI | D1: Upper_CI | E1: Treatment | F1: Distance MD | G1: Lower_CI | H1: Upper_CI | I1: Treatment | J1: Distance totale | K1: Lower_CI | L1: Upper_CI
A2: 8812.454 | B2: 8.1422731 | C2: 10.477422 | D2: 5.8071241 | E2: 8812.454 | F2: 1.609304 | G2: 2.1487446 | H2: 1.0698633 | I2: 8812.454 | J2: 20.226135 | K2: 24.555192 | L2: 15.897078
A3: 10988.071 | B3: 7.9489622 | C3: 11.056144 | D3: 4.84178 | E3: 9680.753 | F3: 1.5844395 | G3: 2.1578311 | H3: 1.0110478 | I3: 10549.053 | J3: 19.254516 | K3: 24.051083 | L3: 14.457948
A4: 13588.102 | B4: 7.6910141 | C4: 10.522438 | D4: 4.8595906 | E4: 12719.802 | F4: 1.5172573 | G4: 2.1678468 | H4: 0.86666782 | I4: 13433.518 | J4: 17.746805 | K4: 21.699331 | L4: 13.794279
A5: 14890.551 | B5: 7.5507762 | C5: 9.5756006 | D5: 5.5259519 | E5: 14022.251 | F5: 1.4979144 | G5: 2.0495614 | H5: 0.94626744 | I5: 14890.551 | J5: 17.035582 | K5: 19.596549 | L5: 14.474614
A6: 15758.85 | B6: 7.4531969 | C6: 9.3804733 | D6: 5.5259206 | E6: 14890.551 | F6: 1.4881689 | G6: 1.9120106 | H6: 1.0643273 | I6: 15758.85 | J6: 16.627815 | K6: 18.98795 | L6: 14.267679
A7: 17495.45 | B7: 7.2482283 | C7: 9.0363696 | D7: 5.460087 | E7: 15758.85 | F7: 1.4809433 | G7: 1.8839232 | H7: 1.0779635 | I7: 17495.45 | J7: 15.8483 | K7: 18.026851 | L7: 13.669748
A8: 17929.6 | B8: 7.1949424 | C8: 8.7902498 | D8: 5.5996351 | E8: 17495.45 | F8: 1.4740516 | G8: 1.89487 | H8: 1.0532332 | I8: 18363.749 | J8: 15.476552 | K8: 17.301418 | L8: 13.651687
A9: 18363.749 | B9: 7.1408392 | C9: 8.7497037 | D9: 5.5319746 | E9: 18363.749 | F9: 1.4743855 | G9: 1.8309237 | H9: 1.1178473 | I9: 18797.899 | J9: 15.295181 | K9: 17.288402 | L9: 13.30196
A10: 18797.899 | B10: 7.0859183 | C10: 8.8494933 | D10: 5.3223433 | E10: 18797.899 | F10: 1.4754974 | G10: 1.8693782 | H10: 1.0816166 | I10: 19232.049 | J10: 15.116811 | K10: 17.187213 | L10: 13.04641
A11: 20100.348 | B11: 6.916251 | C11: 9.2672241 | D11: 4.5652778 | E11: 19232.049 | F11: 1.4772393 | G11: 1.9002003 | H11: 1.0542783 | I11: 20100.348 | J11: 14.769077 | K11: 17.261829 | L11: 12.276326
A12: 21043.111 | B12: 6.788849 | C12: 8.9984412 | D12: 4.5792568 | E12: 20100.348 | F12: 1.4826129 | G12: 1.9829746 | H12: 0.98225113 | I12: 21402.798 | J12: 14.269988 | K12: 16.337563 | L12: 12.202412
A13: 21836.948 | B13: 6.6785828 | C13: 8.6974107 | D13: 4.6597549 | E13: 20570.546 | F13: 1.4865745 | G13: 1.9998619 | H13: 0.97328711 | I13: 21836.948 | J13: 14.109628 | K13: 16.127907 | L13: 12.091349
... A54: 47017.636 | B54: 1.762554 | C54: 4.299506 | D54: -0.77439802 | E54: 41373.688 | F54: 2.401403 | G54: 2.7190733 | H54: 2.0837327 | I54: 40408.692 | J54: 10.060414 | K54: 11.940871 | L54: 8.1799583
E55: 41807.838 | F55: 2.4359029 | G55: 2.7454084 | H55: 2.1263973 | I55: 40939.538 | J55: 10.025418 | K55: 11.985127 | L55: 8.0657084
E56: 42241.988 | F56: 2.4710327 | G56: 2.8359484 | H56: 2.106117 | I56: 41373.688 | J56: 10.000131 | K56: 11.84667 | L56: 8.1535933
E57: 43978.587 | F57: 2.6178516 | G57: 3.2377094 | H57: 1.9979938 | I57: 41807.838 | J57: 9.977847 | K57: 11.664731 | L57: 8.2909633
E58: 45281.036 | F58: 2.7345803 | G58: 3.4931521 | H58: 1.9760084 | I58: 42241.988 | J58: 9.9585641 | K58: 12.061915 | L58: 7.8552131
I59: 43978.587 | J59: 9.9114492 | K59: 13.427387 | L59: 6.3955116
I60: 46995.928 | J60: 9.943803 | K60: 13.396577 | L60: 6.491029

Sheet R_EMPHAB
A1: Treatment | B1: Distance TIM | C1: Lower_CI | D1: Upper_CI | E1: Treatment | F1: Distance MD | G1: Lower_CI | H1: Upper_CI | I1: Treatment | J1: Distance totale | K1: Lower_CI | L1: Upper_CI
A2: 0.095 | B2: 8.6965102 | C2: 14.837087 | D2: 2.5559332 | E2: 0.095 | F2: 0.68599353 | G2: 2.1297906 | H2: -0.75780349 | I2: 0.095 | J2: 18.844302 | K2: 27.672914 | L2: 10.01569 | N2: =MIN(J:J) -> 11.509264
A3: 0.195 | B3: 7.4619643 | C3: 12.371206 | D3: 2.5527221 | E3: 0.195 | F3: 0.87146044 | G3: 2.1051562 | H3: -0.36223531 | I3: 0.195 | J3: 16.421792 | K3: 23.50394 | L3: 9.3396433 | N3: =MAX(J:J) -> 18.844302
A4: 0.295 | B4: 6.4797662 | C4: 10.635587 | D4: 2.323945 | E4: 0.295 | F4: 1.0518262 | G4: 2.1198149 | H4: -0.016162545 | I4: 0.295 | J4: 14.479283 | K4: 20.385668 | L4: 8.572898
A5: 0.395 | B5: 5.7499158 | C5: 8.9144018 | D5: 2.5854299 | E5: 0.395 | F5: 1.2270907 | G5: 2.0497419 | H5: 0.40443951 | I5: 0.395 | J5: 13.016776 | K5: 17.354861 | L5: 8.6786911
A6: 0.495 | B6: 5.2724132 | C6: 8.0400851 | D6: 2.5047414 | E6: 0.495 | F6: 1.3972541 | G6: 2.155622 | H6: 0.63888611 | I6: 0.495 | J6: 12.03427 | K6: 15.691626 | L6: 8.3769147
A7: 0.695 | B7: 5.0744514 | C7: 8.2540343 | D7: 1.8948685 | E7: 0.695 | F7: 1.7222772 | G7: 2.6941756 | H7: 0.75037883 | I7: 0.695 | J7: 11.509264 | K7: 16.005095 | L7: 7.0134325
A8: 0.795 | B8: 5.3539921 | C8: 8.9747217 | D8: 1.7332625 | E8: 0.795 | F8: 1.8771371 | G8: 2.9464779 | H8: 0.8077962 | I8: 0.795 | J8: 11.966763 | K8: 17.317377 | L8: 6.6161485
A9: 0.895 | B9: 5.8858806 | C9: 13.06244 | D9: -1.2906791 | E9: 0.895 | F9: 2.0268957 | G9: 3.9161272 | H9: 0.13766414 | I9: 0.895 | J9: 12.904263 | K9: 22.869791 | L9: 2.9387343
A10: 0.995 | B10: 6.6701168 | C10: 11.167441 | D10: 2.1727928 | E10: 0.995 | F10: 2.1715531 | G10: 3.2504344 | H10: 1.0926719 | I10: 0.995 | J10: 14.321765 | K10: 20.790253 | L10: 7.8532766

Sheet ROAD_DENS
A1: Treatment | B1: Distance TIM | C1: Lower_CI | D1: Upper_CI | E1: Treatment | F1: Distance MD | G1: Lower_CI | H1: Upper_CI | I1: Treatment | J1: Distance totale | K1: Lower_CI | L1: Upper_CI
A2: 4.882 | B2: 10.456211 | C2: 14.138864 | D2: 6.7735586 | E2: 4.848 | F2: 1.1461001 | G2: 1.9155963 | H2: 0.37660384 | I2: 4.882 | J2: 16.07273 | K2: 22.664102 | L2: 9.4813577 | N2: =MIN(J:J) -> 9.6760082
A3: 5.495 | B3: 10.277192 | C3: 14.050794 | D3: 6.5035893 | E3: 5.272 | F3: 1.1594236 | G3: 1.9509744 | H3: 0.36787276 | I3: 5.495 | J3: 15.899834 | K3: 22.496845 | L3: 9.3028223 | N3: =MAX(J:J) -> 16.07273
A4: 6.348 | B4: 10.033527 | C4: 13.910933 | D4: 6.1561219 | E4: 5.956 | F4: 1.1807217 | G4: 2.0065522 | H4: 0.3548912 | I4: 6.108 | J4: 15.729305 | K4: 22.532159 | L4: 8.9264513
A5: 7.334 | B5: 9.759766 | C5: 13.592032 | D5: 5.9274998 | E5: 7.323 | F5: 1.2225635 | G5: 2.0938867 | H5: 0.35124036 | I5: 7.334 | J5: 15.395352 | K5: 21.934287 | L5: 8.8564168
A6: 7.946 | B6: 9.5941034 | C6: 13.412969 | D6: 5.7752375 | E6: 8.007 | F6: 1.2431379 | G6: 2.1082851 | H6: 0.37799064 | I6: 7.946 | J6: 15.232192 | K6: 21.645163 | L6: 8.8192209
A7: 8.56 | B7: 9.4311769 | C7: 13.171498 | D7: 5.6908562 | E7: 8.69 | F7: 1.2634413 | G7: 2.1305023 | H7: 0.39638038 | I7: 8.56 | J7: 15.07087 | K7: 21.299051 | L7: 8.842689
A8: 9.172 | B8: 9.272048 | C8: 12.871307 | D8: 5.672789 | E8: 9.374 | F8: 1.2835333 | G8: 2.1437274 | H8: 0.4233392 | I8: 9.172 | J8: 14.912437 | K8: 20.840202 | L8: 8.9846725
A9: 9.785 | B9: 9.1159288 | C9: 12.578233 | D9: 5.6536249 | E9: 9.571 | F9: 1.2892752 | G9: 2.1351274 | H9: 0.44342304 | I9: 10.398 | J9: 14.602154 | K9: 19.960245 | L9: 9.2440625
A10: 10.398 | B10: 8.9630817 | C10: 12.292449 | D10: 5.6337144 | E10: 10.742 | F10: 1.3229931 | G10: 2.1066278 | H10: 0.53935833 | I10: 11.012 | J10: 14.450318 | K10: 19.538509 | L10: 9.3621273
A11: 11.012 | B11: 8.8132656 | C11: 11.981818 | D11: 5.6447135 | E11: 11.426 | F11: 1.3423609 | G11: 2.1083187 | H11: 0.57640316 | I11: 11.624 | J11: 14.301341 | K11: 19.072726 | L11: 9.5299562
A12: 12.238 | B12: 8.5239436 | C12: 11.352637 | D12: 5.6952506 | E12: 12.11 | F12: 1.3614874 | G12: 2.1091657 | H12: 0.61380911 | I12: 12.238 | J12: 14.154249 | K12: 18.61977 | L12: 9.6887273
A13: 12.85 | B13: 8.3844162 | C13: 11.09579 | D13: 5.6730425 | E13: 12.793 | F13: 1.3803451 | G13: 2.0909092 | H13: 0.669781 | I13: 12.85 | J13: 14.01 | K13: 18.290422 | L13: 9.7295772
A14: 13.462 | B14: 8.2481504 | C14: 10.845348 | D14: 5.6509534 | E14: 13.477 | F14: 1.3989892 | G14: 2.0806516 | H14: 0.71732678 | I14: 13.462 | J14: 13.86811 | K14: 17.916124 | L14: 9.8200971
A15: 14.076 | B15: 8.114717 | C15: 10.570343 | D15: 5.6590909 | E15: 14.161 | F15: 1.4173919 | G15: 2.0972846 | H15: 0.73749924 | I15: 14.076 | J15: 13.728129 | K15: 17.498595 | L15: 9.9576633
... A55: 49.012 | B55: 5.9301363 | C55: 9.5099626 | D55: 2.3503099 | E55: 56.978 | F55: 2.0889042 | G55: 3.1201877 | H55: 1.0576206 | I55: 44.722 | J55: 9.7595746 | K55: 15.887956 | L55: 3.631193
A56: 50.852 | B56: 6.1097103 | C56: 9.9597397 | D56: 2.259681 | I56: 49.012 | J56: 9.6762227 | K56: 14.794785 | L56: 4.5576606
A57: 53.916 | B57: 6.4741639 | C57: 10.310284 | D57: 2.6380438 | I57: 50.852 | J57: 9.6760082 | K57: 15.146887 | L57: 4.2051299
A58: 55.754 | B58: 6.7320182 | C58: 10.309559 | D58: 3.1544773 | I58: 53.916 | J58: 9.7229907 | K58: 15.032246 | L58: 4.4137359
A59: 56.98 | B59: 6.9203705 | C59: 10.956431 | D59: 2.8843105 | I59: 54.57 | J59: 9.7406798 | K59: 14.827023 | L59: 4.6543364
I60: 55.754 | J60: 9.7795601 | K60: 14.703703 | L60: 4.8554175
I61: 56.98 | J61: 9.8291284 | K61: 15.423496 | L61: 4.2347604

Sheet TROTT_DENS
A1: Treatment | B1: Distance TIM | C1: Lower_CI | D1: Upper_CI | E1: Treatment | F1: Distance MD | G1: Lower_CI | H1: Upper_CI | I1: Treatment | J1: Distance totale | K1: Lower_CI | L1: Upper_CI
A2: 0.003 | B2: 7.5145656 | C2: 14.02992 | D2: 0.99921162 | E2: 0.001 | F2: 1.4112886 | G2: 2.3235779 | H2: 0.49899927 | I2: 0.003 | J2: 16.936684 | K2: 22.889316 | L2: 10.984053 | N2: =MIN(J:J) -> 10.684311
A3: 0.005 | B3: 7.3825519 | C3: 13.245331 | D3: 1.5197724 | E3: 0.003 | F3: 1.4363414 | G3: 2.2407516 | H3: 0.63193132 | I3: 0.005 | J3: 16.609682 | K3: 21.962796 | L3: 11.256568 | N3: =MAX(J:J) -> 16.936684
A4: 0.007 | B4: 7.2519166 | C4: 12.767409 | D4: 1.7364245 | E4: 0.004 | F4: 1.4488022 | G4: 2.2101899 | H4: 0.68741457 | I4: 0.007 | J4: 16.291462 | K4: 21.412915 | L4: 11.170009
A5: 0.009 | B5: 7.1226596 | C5: 12.359697 | D5: 1.8856225 | E5: 0.005 | F5: 1.4612193 | G5: 2.2197054 | H5: 0.70273318 | I5: 0.009 | J5: 15.982023 | K5: 20.882157 | L5: 11.08189
A6: 0.01 | B6: 7.058548 | C6: 12.058038 | D6: 2.0590584 | E6: 0.007 | F6: 1.4859222 | G6: 2.2300369 | H6: 0.74180748 | I6: 0.01 | J6: 15.830597 | K6: 20.458554 | L6: 11.202641
A7: 0.012 | B7: 6.9313586 | C7: 11.624519 | D7: 2.2381978 | E7: 0.009 | F7: 1.5104501 | G7: 2.2479457 | H7: 0.7729546 | I7: 0.012 | J7: 15.534332 | K7: 20.013176 | L7: 11.055488
A8: 0.014 | B8: 6.8055476 | C8: 11.352592 | D8: 2.2585027 | E8: 0.01 | F8: 1.5226485 | G8: 2.2398078 | H8: 0.80548917 | I8: 0.014 | J8: 15.246848 | K8: 19.689484 | L8: 10.804213
A9: 0.016 | B9: 6.6811149 | C9: 10.993877 | D9: 2.3683522 | E9: 0.012 | F9: 1.5469139 | G9: 2.256616 | H9: 0.83721186 | I9: 0.016 | J9: 14.968147 | K9: 19.221844 | L9: 10.71445
A10: 0.018 | B10: 6.5580606 | C10: 10.647872 | D10: 2.4682487 | E10: 0.014 | F10: 1.5710044 | G10: 2.2988308 | H10: 0.84317806 | I10: 0.018 | J10: 14.698227 | K10: 18.771787 | L10: 10.624668
A11: 0.02 | B11: 6.4363846 | C11: 10.402353 | D11: 2.4704162 | E11: 0.016 | F11: 1.59492 | G11: 2.314805 | H11: 0.87503498 | I11: 0.02 | J11: 14.43709 | K11: 18.38898 | L11: 10.485199
A12: 0.022 | B12: 6.316087 | C12: 10.120814 | D12: 2.5113602 | E12: 0.018 | F12: 1.6186605 | G12: 2.3301872 | H12: 0.90713383 | I12: 0.022 | J12: 14.184734 | K12: 18.070559 | L12: 10.298909
A13: 0.024 | B13: 6.1971678 | C13: 9.8485188 | D13: 2.5458168 | E13: 0.02 | F13: 1.6422261 | G13: 2.3629937 | H13: 0.9214585 | I13: 0.024 | J13: 13.94116 | K13: 17.717194 | L13: 10.165127
A14: 0.026 | B14: 6.0796269 | C14: 9.5852896 | D14: 2.5739643 | E14: 0.022 | F14: 1.6656167 | G14: 2.3956663 | H14: 0.93556715 | I14: 0.026 | J14: 13.706368 | K14: 17.37873 | L14: 10.034007
A15: 0.028 | B15: 5.9634645 | C15: 9.3701046 | D15: 2.5568243 | E15: 0.024 | F15: 1.6888324 | G15: 2.4097207 | H15: 0.9679441 | I15: 0.028 | J15: 13.480359 | K15: 17.102025 | L15: 9.8586922
... A46: 0.126 | B46: 1.9600016 | C46: 6.2555226 | D46: -2.3355194 | E46: 0.111 | F46: 2.5293635 | G46: 3.9555978 | H46: 1.1031293 | I46: 0.121 | J46: 12.669472 | K46: 18.153885 | L46: 7.185059
E47: 0.121 | F47: 2.6047612 | G47: 3.7597903 | H47: 1.449732 | I47: 0.126 | J47: 13.163771 | K47: 19.064081 | L47: 7.2634606
E48: 0.126 | F48: 2.6408196 | G48: 3.6959021 | H48: 1.5857372

Sheet TYPO_TD
A1: Treatment | B1: Distance TIM | C1: Lower_CI | D1: Upper_CI | E1: Treatment | F1: Distance MD | G1: Lower_CI | H1: Upper_CI | I1: Treatment | J1: Distance totale | K1: Lower_CI | L1: Upper_CI
A2: 1 | B2: 4.843272 | C2: 1.931543 | D2: 7.755001 | E2: 1 | F2: 2.1180978 | G2: 1.3486016 | H2: 2.8875941 | I2: 1 | J2: 12.936976 | K2: 8.872318 | L2: 17.04534 | N2: =MIN(J:J) -> 11.888032
A3: 2 | B3: 5.160391 | C3: 1.383792 | D3: 8.93699 | E3: 2 | F3: 2.094299 | G3: 1.1423449 | H3: 3.0462531 | I3: 2 | J3: 11.888032 | K3: 6.730724 | L3: 17.089046 | N3: =MAX(J:J) -> 21.19741
A4: 3 | B4: 6.745986 | C4: 4.237863 | D4: 9.254109 | E4: 3 | F4: 1.6262549 | G4: 1.0312836 | H4: 2.2291591 | I4: 3 | J4: 14.073332 | K4: 10.751676 | L4: 17.394988
A5: 4 | B5: 8.418068 | C5: 5.073904 | D5: 11.762232 | E5: 4 | F5: 1.3644675 | G5: 0.5791054 | H5: 2.1498296 | I5: 4 | J5: 17.569812 | K5: 13.1118 | L5: 21.984118
A6: 5 | B6: 9.917176 | C6: 5.852287 | D6: 13.982065 | E6: 5 | F6: 1.4279311 | G6: 0.47597704 | H6: 2.3719523 | I6: 5 | J6: 21.19741 | K6: 15.821572 | L6: 26.573248
A7: 6 | B7: 11.041507 | C7: 6.05409 | D7: 16.028924 | E7: 6 | F7: 1.4120652 | G7: 0.24592147 | H7: 2.578209 | I7: 6 | J7: 20.76035 | K7: 14.029626 | L7: 27.447368
A8: 7 | B8: 11.041507 | C8: 6.05409 | D8: 16.028924 | E8: 7 | F8: 1.4120652 | G8: 0.24592147 | H8: 2.578209 | I8: 7 | J8: 20.76035 | K8: 14.029626 | L8: 27.447368

Sheet W_OeV_KLASSE
A1: Treatment | B1: Distance TIM | C1: Lower_CI | D1: Upper_CI | E1: Treatment | F1: Distance MD | G1: Lower_CI | H1: Upper_CI | I1: Treatment | J1: Distance totale | K1: Lower_CI | L1: Upper_CI
A2: A | B2: 4.237863 | C2: 2.825242 | D2: 5.650484 | E2: A | F2: 1.7452492 | G2: 1.3803334 | H2: 2.1101649 | I2: A | J2: 10.314616 | K2: 8.391552 | L2: 12.23768 | N2: =MIN(J:J) -> 10.314616
A3: B | B3: 6.025261 | C3: 4.439666 | D3: 7.582027 | E3: B | F3: 1.6579867 | G3: 1.2613392 | H3: 2.0546342 | I3: B | J3: 12.587328 | K3: 10.445734 | L3: 14.685216 | N3: =MAX(J:J) -> 19.318052
A4: C | B4: 6.745986 | C4: 4.958588 | D4: 8.533384 | E4: C | F4: 1.285138 | G4: 0.84882572 | H4: 1.7293833 | I4: C | J4: 14.816334 | K4: 12.45621 | L4: 17.176458
A5: D | B5: 7.697343 | C5: 5.909945 | D5: 9.455912 | E5: D | F5: 1.0471495 | G5: 0.6108372 | H5: 1.4755288 | I5: D | J5: 16.433456 | K5: 14.117038 | L5: 18.749874
A6: Hors desserte | B6: 7.697343 | C6: 5.909945 | D6: 9.455912 | E6: Hors desserte | F6: 1.0550824 | G6: 0.33318393 | H6: 1.769048 | I6: Hors desserte | J6: 19.318052 | K6: 15.384512 | L6: 23.251592

Sheet Places_Parking
A1: Treatment | B1: Distance TIM | C1: Lower_CI | D1: Upper_CI | E1: Treatment | F1: Distance MD | G1: Lower_CI | H1: Upper_CI | I1: Treatment | J1: Distance totale | K1: Lower_CI | L1: Upper_CI
A2: 0 | B2: 3.315335 | C2: 1.499108 | D2: 5.131562 | E2: 0 | F2: 2.0625672 | G2: 1.5945231 | H2: 2.5385442 | I2: 0 | J2: 10.48944 | K2: 7.954492 | L2: 12.980682 | N2: =MIN(J:J) -> 10.48944
A3: 0.1 | B3: =((B$12-B$2)*$A3) + B$2 -> 3.5517328 | C3: =((C$12-C$2)*$A3) + C$2 -> 1.8046954 | D3: =((D$12-D$2)*$A3) + D$2 -> 5.3016531 | E3: 0.1 | F3: =((F$12-F$2)*$A3) + F$2 -> 2.032422 | G3: =((G$12-G$2)*$A3) + G$2 -> 1.5818304 | H3: =((H$12-H$2)*$A3) + H$2 -> 2.4901532 | I3: 0.1 | J3: =((J$12-J$2)*$A3) + J$2 -> 10.664264 | K3: =((K$12-K$2)*$A3) + K$2 -> 8.2254692 | L3: =((L$12-L$2)*$A3) + L$2 -> 13.063723 | N3: =MAX(J:J) -> 15.690454
A4: 0.2 | B4: =((B$12-B$2)*$A4) + B$2 -> 3.7881306 | C4: =((C$12-C$2)*$A4) + C$2 -> 2.1102828 | D4: =((D$12-D$2)*$A4) + D$2 -> 5.4717442 | E4: 0.2 | F4: =((F$12-F$2)*$A4) + F$2 -> 2.0022768 | G4: =((G$12-G$2)*$A4) + G$2 -> 1.5691376 | H4: =((H$12-H$2)*$A4) + H$2 -> 2.4417622 | I4: 0.2 | J4: =((J$12-J$2)*$A4) + J$2 -> 10.839088 | K4: =((K$12-K$2)*$A4) + K$2 -> 8.4964464 | L4: =((L$12-L$2)*$A4) + L$2 -> 13.146765
A5: 0.3 | B5: =((B$12-B$2)*$A5) + B$2 -> 4.0245284 | C5: =((C$12-C$2)*$A5) + C$2 -> 2.4158702 | D5: =((D$12-D$2)*$A5) + D$2 -> 5.6418353 | E5: 0.3 | F5: =((F$12-F$2)*$A5) + F$2 -> 1.9721315 | G5: =((G$12-G$2)*$A5) + G$2 -> 1.5564449 | H5: =((H$12-H$2)*$A5) + H$2 -> 2.3933712 | I5: 0.3 | J5: =((J$12-J$2)*$A5) + J$2 -> 11.013912 | K5: =((K$12-K$2)*$A5) + K$2 -> 8.7674236 | L5: =((L$12-L$2)*$A5) + L$2 -> 13.229806
A6: 0.4 | B6: =((B$12-B$2)*$A6) + B$2 -> 4.2609262 | C6: =((C$12-C$2)*$A6) + C$2 -> 2.7214576 | D6: =((D$12-D$2)*$A6) + D$2 -> 5.8119264 | E6: 0.4 | F6: =((F$12-F$2)*$A6) + F$2 -> 1.9419863 | G6: =((G$12-G$2)*$A6) + G$2 -> 1.5437522 | H6: =((H$12-H$2)*$A6) + H$2 -> 2.3449802 | I6: 0.4 | J6: =((J$12-J$2)*$A6) + J$2 -> 11.188736 | K6: =((K$12-K$2)*$A6) + K$2 -> 9.0384008 | L6: =((L$12-L$2)*$A6) + L$2 -> 13.312848
A7: 0.5 | B7: =((B$12-B$2)*$A7) + B$2 -> 4.497324 | C7: =((C$12-C$2)*$A7) + C$2 -> 3.027045 | D7: =((D$12-D$2)*$A7) + D$2 -> 5.9820175 | E7: 0.5 | F7: =((F$12-F$2)*$A7) + F$2 -> 1.9118411 | G7: =((G$12-G$2)*$A7) + G$2 -> 1.5310595 | H7: =((H$12-H$2)*$A7) + H$2 -> 2.2965892 | I7: 0.5 | J7: =((J$12-J$2)*$A7) + J$2 -> 11.36356 | K7: =((K$12-K$2)*$A7) + K$2 -> 9.309378 | L7: =((L$12-L$2)*$A7) + L$2 -> 13.395889
A8: 0.6 | B8: =((B$12-B$2)*$A8) + B$2 -> 4.7337218 | C8: =((C$12-C$2)*$A8) + C$2 -> 3.3326324 | D8: =((D$12-D$2)*$A8) + D$2 -> 6.1521086 | E8: 0.6 | F8: =((F$12-F$2)*$A8) + F$2 -> 1.8816959 | G8: =((G$12-G$2)*$A8) + G$2 -> 1.5183668 | H8: =((H$12-H$2)*$A8) + H$2 -> 2.2481982 | I8: 0.6 | J8: =((J$12-J$2)*$A8) + J$2 -> 11.538384 | K8: =((K$12-K$2)*$A8) + K$2 -> 9.5803552 | L8: =((L$12-L$2)*$A8) + L$2 -> 13.47893
A9: 0.7 | B9: =((B$12-B$2)*$A9) + B$2 -> 4.9701196 | C9: =((C$12-C$2)*$A9) + C$2 -> 3.6382198 | D9: =((D$12-D$2)*$A9) + D$2 -> 6.3221997 | E9: 0.7 | F9: =((F$12-F$2)*$A9) + F$2 -> 1.8515507 | G9: =((G$12-G$2)*$A9) + G$2 -> 1.505674 | H9: =((H$12-H$2)*$A9) + H$2 -> 2.1998072 | I9: 0.7 | J9: =((J$12-J$2)*$A9) + J$2 -> 11.713208 | K9: =((K$12-K$2)*$A9) + K$2 -> 9.8513324 | L9: =((L$12-L$2)*$A9) + L$2 -> 13.561972
A10: 0.8 | B10: =((B$12-B$2)*$A10) + B$2 -> 5.2065174 | C10: =((C$12-C$2)*$A10) + C$2 -> 3.9438072 | D10: =((D$12-D$2)*$A10) + D$2 -> 6.4922908 | E10: 0.8 | F10: =((F$12-F$2)*$A10) + F$2 -> 1.8214055 | G10: =((G$12-G$2)*$A10) + G$2 -> 1.4929813 | H10: =((H$12-H$2)*$A10) + H$2 -> 2.1514162 | I10: 0.8 | J10: =((J$12-J$2)*$A10) + J$2 -> 11.888032 | K10: =((K$12-K$2)*$A10) + K$2 -> 10.12231 | L10: =((L$12-L$2)*$A10) + L$2 -> 13.645013
A11: 0.9 | B11: =((B$12-B$2)*$A11) + B$2 -> 5.4429152 | C11: =((C$12-C$2)*$A11) + C$2 -> 4.2493946 | D11: =((D$12-D$2)*$A11) + D$2 -> 6.6623819 | E11: 0.9 | F11: =((F$12-F$2)*$A11) + F$2 -> 1.7912603 | G11: =((G$12-G$2)*$A11) + G$2 -> 1.4802886 | H11: =((H$12-H$2)*$A11) + H$2 -> 2.1030252 | I11: 0.9 | J11: =((J$12-J$2)*$A11) + J$2 -> 12.062856 | K11: =((K$12-K$2)*$A11) + K$2 -> 10.393287 | L11: =((L$12-L$2)*$A11) + L$2 -> 13.728055
A12: 1 | B12: 5.679313 | C12: 4.554982 | D12: 6.832473 | E12: 1 | F12: 1.7611151 | G12: 1.4675959 | H12: 2.0546342 | I12: 1 | J12: 12.23768 | K12: 10.664264 | L12: 13.811096
A13: 2 | B13: 8.821674 | C13: 6.861302 | D13: 10.753217 | E13: 2 | F13: 1.293071 | G13: 0.82502687 | H13: 1.7611151 | I13: 2 | J13: 15.690454 | K13: 13.068094 | L13: 18.312814
A14: 3 | B14: 8.389239 | C14: 5.045075 | D14: 11.762232 | E14: 3 | F14: 1.5072606 | G14: 0.70603261 | H14: 2.3084887 | I14: 3 | J14: 14.947452 | K14: 10.533146 | L14: 19.405464
A15: 4 | B15: 8.821674 | C15: 5.333365 | D15: 12.309983 | E15: 4 | F15: 0.91228933 | G15: 0.031731803 | H15: 1.7849139 | I15: 4 | J15: 15.253394 | K15: 10.402028 | L15: 20.061054
A16: 5 | B16: 8.821674 | C16: 5.333365 | D16: 12.309983 | E16: 5 | F16: 0.91228933 | G16: 0.031731803 | H16: 1.7849139 | I16: 5 | J16: 15.253394 | K16: 10.402028 | L16: 20.061054

Sheet enquêtes TIM
A1: y = ax^2 + bx + c | B1: a | C1: b | D1: c | E1: R2 | F1: Value | G1: Distance TIM | P1: A | Q1: 1
A2: Acc. gravitaire TIM | B2: 0 | C2: -0.00030435227 | D2: 18.847769 | E2: 0.35195129 | F2: =INDEX(RESULTATS!$C$2:$C$10,MATCH('enquêtes TIM'!A2,RESULTATS!$B$2:$B$10,0)) -> 25676 | G2: =(B2*(F2^2)) + (C2*F2) + D2 -> 11.033221 | P2: B | Q2: 2
A3: Acc. gravitaire TP | B3: 0 | C3: -9.6662184e-05 | D3: 14.625391 | E3: 0.48449093 | F3: =INDEX(RESULTATS!$C$2:$C$10,MATCH('enquêtes TIM'!A3,RESULTATS!$B$2:$B$10,0)) -> 13868 | G3: =(B3*(F3^2)) + (C3*F3) + D3 -> 13.28488 | P3: C | Q3: 3
A4: Dens. bâtiments (bât/m2) | B4: 0 | C4: -29.21144 | D4: 14.1678 | E4: 0.2842538 | F4: =INDEX(RESULTATS!$C$2:$C$10,MATCH('enquêtes TIM'!A4,RESULTATS!$B$2:$B$10,0)) -> 0.08 | G4: =(B4*(F4^2)) + (C4*F4) + D4 -> 11.830885 | P4: D | Q4: 4
A5: Dens. population (pop/ha) | B5: 0 | C5: -0.034336077 | D5: 13.211855 | E5: 0.32344373 | F5: =INDEX(RESULTATS!$C$2:$C$10,MATCH('enquêtes TIM'!A5,RESULTATS!$B$2:$B$10,0)) -> 43 | G5: =(B5*(F5^2)) + (C5*F5) + D5 -> 11.735404
A6: Entropie utilisation du sol | B6: 0 | C6: -14.437143 | D6: 19.555831 | E6: 0.13815134 | F6: =INDEX(RESULTATS!$C$2:$C$10,MATCH('enquêtes TIM'!A6,RESULTATS!$B$2:$B$10,0)) -> #N/A | G6: =(B6*(F6^2)) + (C6*F6) + D6 -> #N/A
A7: N. intersections feux rouges (/km2) | B7: 0 | C7: -0.018272946 | D7: 12.720666 | E7: 0.4810787 | F7: =INDEX(RESULTATS!$C$2:$C$10,MATCH('enquêtes TIM'!A7,RESULTATS!$B$2:$B$10,0)) -> #N/A | G7: =(B7*(F7^2)) + (C7*F7) + D7 -> #N/A
A8: Charge max. du réseau (voit/j) | B8: 0 | C8: -0.0003687582 | D8: 13.730319 | E8: 0.18350408 | F8: =INDEX(RESULTATS!$C$2:$C$10,MATCH('enquêtes TIM'!A8,RESULTATS!$B$2:$B$10,0)) -> #N/A | G8: =(B8*(F8^2)) + (C8*F8) + D8 -> #N/A
A9: Ratio emplois - habitants | B9: 0 | C9: -13.983391 | D9: 17.116235 | E9: 0.38827534 | F9: =INDEX(RESULTATS!$C$2:$C$10,MATCH('enquêtes TIM'!A9,RESULTATS!$B$2:$B$10,0)) -> 0.205 | G9: =(B9*(F9^2)) + (C9*F9) + D9 -> 14.24964
A10: Densité routière (km/km2) | B10: 0 | C10: -0.3217402 | D10: 17.195165 | E10: 0.40428276 | F10: =INDEX(RESULTATS!$C$2:$C$10,MATCH('enquêtes TIM'!A10,RESULTATS!$B$2:$B$10,0)) -> 17 | G10: =(B10*(F10^2)) + (C10*F10) + D10 -> 11.725582
A11: Surf. couverte par trottoirs (km2/km2) | B11: 0 | C11: -108.55291 | D11: 13.118685 | E11: 0.33892296 | F11: =INDEX(RESULTATS!$C$2:$C$10,MATCH('enquêtes TIM'!A11,RESULTATS!$B$2:$B$10,0)) -> 0.015 | G11: =(B11*(F11^2)) + (C11*F11) + D11 -> 11.490391
A12: Typologie courtes distances | B12: 0 | C12: 2.5213966 | D12: 3.120194 | E12: 0.28650919 | F12: =INDEX(RESULTATS!$C$2:$C$10,MATCH('enquêtes TIM'!A12,RESULTATS!$B$2:$B$10,0)) -> 4 | G12: =(B12*(F12^2)) + (C12*F12) + D12 -> 13.205781
A13: Classe de desserte TP | B13: 0 | C13: 0.6658165 | D13: 8.0070695 | E13: 0.12757889 | F13: =INDEX(Q1:Q4,MATCH(INDEX(RESULTATS!$C$2:$C$10,MATCH('enquêtes TIM'!A13,RESULTATS!$B$2:$B$10,0)),P1:P4,0)) -> 2 | G13: =(B13*(F13^2)) + (C13*F13) + D13 -> 9.3387025
A30: Valeur basse enquêtes | B30: 19370 | C30: =(B30*$C$2) + $D$2 -> 12.952466
B31: =F2 -> 25676 | C31: =(B31*$C$2) + $D$2 -> 11.033221
A32: Valeur haute enquêtes | B32: 43803 | C32: =(B32*$C$2) + $D$2 -> 5.5162271

Sheet enquêtes MD
A1: y = ax^2 + bx + c | B1: a | C1: b | D1: c | E1: R2 | F1: Value | G1: Distance TIM | P1: A | Q1: 1
A2: Acc. gravitaire TIM | B2: 0 | C2: 1.1646185e-05 | D2: 1.7369338 | E2: 0.078173262 | F2: =INDEX(RESULTATS!$C$2:$C$10,MATCH('enquêtes TIM'!A2,RESULTATS!$B$2:$B$10,0)) -> 25676 | G2: =(B2*(F2^2)) + (C2*F2) + D2 -> 2.0359613 | P2: B | Q2: 2
A3: Acc. gravitaire TP | B3: 0 | C3: 5.1116247e-06 | D3: 1.8198455 | E3: 0.13181109 | F3: =INDEX(RESULTATS!$C$2:$C$10,MATCH('enquêtes TIM'!A3,RESULTATS!$B$2:$B$10,0)) -> 13868 | G3: =(B3*(F3^2)) + (C3*F3) + D3 -> 1.8907335 | P3: C | Q3: 3
A4: Dens. bâtiments (bât/m2) | B4: 0 | C4: 1.2569657 | D4: 1.892554 | E4: 0.075656657 | F4: =INDEX(RESULTATS!$C$2:$C$10,MATCH('enquêtes TIM'!A4,RESULTATS!$B$2:$B$10,0)) -> 0.08 | G4: =(B4*(F4^2)) + (C4*F4) + D4 -> 1.9931113 | P4: D | Q4: 4
A5: Dens. population (pop/ha) | B5: 0 | C5: 0.0003436476 | D5: 2.0647267 | E5: 0.052515953 | F5: =INDEX(RESULTATS!$C$2:$C$10,MATCH('enquêtes TIM'!A5,RESULTATS!$B$2:$B$10,0)) -> 43 | G5: =(B5*(F5^2)) + (C5*F5) + D5 -> 2.0795035
A6: Entropie utilisation du sol | B6: 0 | C6: 1.8152221 | D6: 0.80785528 | E6: 0.083044597 | F6: =INDEX(RESULTATS!$C$2:$C$10,MATCH('enquêtes TIM'!A6,RESULTATS!$B$2:$B$10,0)) -> #N/A | G6: =(B6*(F6^2)) + (C6*F6) + D6 -> #N/A
A7: N. intersections feux rouges (/km2) | B7: 0 | C7: 0.00034209797 | D7: 2.0393462 | E7: 0.060922021 | F7: =INDEX(RESULTATS!$C$2:$C$10,MATCH('enquêtes TIM'!A7,RESULTATS!$B$2:$B$10,0)) -> #N/A | G7: =(B7*(F7^2)) + (C7*F7) + D7 -> #N/A
A8: Charge max. du réseau (voit/j) | B8: 0 | C8: -1.4392012e-05 | D8: 2.2795522 | E8: 0.059337495 | F8: =INDEX(RESULTATS!$C$2:$C$10,MATCH('enquêtes TIM'!A8,RESULTATS!$B$2:$B$10,0)) -> #N/A | G8: =(B8*(F8^2)) + (C8*F8) + D8 -> #N/A
A9: Ratio emplois - habitants | B9: 0 | C9: 1.4653349 | D9: 1.279459 | E9: 0.28662294 | F9: =INDEX(RESULTATS!$C$2:$C$10,MATCH('enquêtes TIM'!A9,RESULTATS!$B$2:$B$10,0)) -> 0.205 | G9: =(B9*(F9^2)) + (C9*F9) + D9 -> 1.5798526
A10: Densité routière (km/km2) | B10: 0 | C10: 0.016265116 | D10: 1.7024618 | E10: 0.10891563 | F10: =INDEX(RESULTATS!$C$2:$C$10,MATCH('enquêtes TIM'!A10,RESULTATS!$B$2:$B$10,0)) -> 17 | G10: =(B10*(F10^2)) + (C10*F10) + D10 -> 1.9789688
A11: Surf. couverte par trottoirs (km2/km2) | B11: 0 | C11: 4.6972023 | D11: 1.9353432 | E11: 0.083888367 | F11: =INDEX(RESULTATS!$C$2:$C$10,MATCH('enquêtes TIM'!A11,RESULTATS!$B$2:$B$10,0)) -> 0.015 | G11: =(B11*(F11^2)) + (C11*F11) + D11 -> 2.0058013
A12: Typologie courtes distances | B12: 0 | C12: -0.21983229 | D12: 2.6383209 | E12: 0.15396205 | F12: =INDEX(RESULTATS!$C$2:$C$10,MATCH('enquêtes TIM'!A12,RESULTATS!$B$2:$B$10,0)) -> 4 | G12: =(B12*(F12^2)) + (C12*F12) + D12 -> 1.7589918
A13: Classe de desserte TP | B13: 0 | C13: 0.098884122 | D13: 1.9208006 | E13: 0.077642773 | F13: =INDEX(Q1:Q4,MATCH(INDEX(RESULTATS!$C$2:$C$10,MATCH('enquêtes TIM'!A13,RESULTATS!$B$2:$B$10,0)),P1:P4,0)) -> 2 | G13: =(B13*(F13^2)) + (C13*F13) + D13 -> 2.1185688

Sheet enquêtes TC
A1: y = ax^2 + bx + c | B1: a | C1: b | D1: c | E1: R2 | F1: Value | G1: Distance TIM | P1: A | Q1: 1
A2: Acc. gravitaire TIM | B2: 0 | C2: -2.458e-05 | D2: 5.2632624 | E2: 0.56277659 | F2: =INDEX(RESULTATS!$C$2:$C$10,MATCH('enquêtes TIM'!A2,RESULTATS!$B$2:$B$10,0)) -> 25676 | G2: =(B2*(F2^2)) + (C2*F2) + D2 -> 4.6321464 | P2: B | Q2: 2
A3: Acc. gravitaire TP | B3: 0 | C3: -1.9732337e-06 | D3: 4.5976161 | E3: 0.50023995 | F3: =INDEX(RESULTATS!$C$2:$C$10,MATCH('enquêtes TIM'!A3,RESULTATS!$B$2:$B$10,0)) -> 13868 | G3: =(B3*(F3^2)) + (C3*F3) + D3 -> 4.5702513 | P3: C | Q3: 3
A4: Dens. bâtiments (bât/m2) | B4: 0 | C4: -3.26988 | D4: 5.0389618 | E4: 0.58913632 | F4: =INDEX(RESULTATS!$C$2:$C$10,MATCH('enquêtes TIM'!A4,RESULTATS!$B$2:$B$10,0)) -> 0.08 | G4: =(B4*(F4^2)) + (C4*F4) + D4 -> 4.7773714 | P4: D | Q4: 4
A5: Dens. population (pop/ha) | B5: 0 | C5: -0.0041188931 | D5: 4.9637798 | E5: 0.62837307 | F5: =INDEX(RESULTATS!$C$2:$C$10,MATCH('enquêtes TIM'!A5,RESULTATS!$B$2:$B$10,0)) -> 43 | G5: =(B5*(F5^2)) + (C5*F5) + D5 -> 4.7866674
A6: Entropie utilisation du sol | B6: 0 | C6: -4.7685967 | D6: 7.893894 | E6: 0.62014468 | F6: =INDEX(RESULTATS!$C$2:$C$10,MATCH('enquêtes TIM'!A6,RESULTATS!$B$2:$B$10,0)) -> #N/A | G6: =(B6*(F6^2)) + (C6*F6) + D6 -> #N/A
A7: N. intersections feux rouges (/km2) | B7: 0 | C7: -0.0014104491 | D7: 4.7561418 | E7: 0.59092415 | F7: =INDEX(RESULTATS!$C$2:$C$10,MATCH('enquêtes TIM'!A7,RESULTATS!$B$2:$B$10,0)) -> #N/A | G7: =(B7*(F7^2)) + (C7*F7) + D7 -> #N/A
A8: Charge max. du réseau (voit/j) | B8: 0 | C8: 1.2090975e-05 | D8: 4.3406409 | E8: 0.49676501 | F8: =INDEX(RESULTATS!$C$2:$C$10,MATCH('enquêtes TIM'!A8,RESULTATS!$B$2:$B$10,0)) -> #N/A | G8: =(B8*(F8^2)) + (C8*F8) + D8 -> #N/A
A9: Ratio emplois - habitants | B9: 0 | C9: 0.41039974 | D9: 4.2566984 | E9: 0.50391217 | F9: =INDEX(RESULTATS!$C$2:$C$10,MATCH('enquêtes TIM'!A9,RESULTATS!$B$2:$B$10,0)) -> 0.205 | G9: =(B9*(F9^2)) + (C9*F9) + D9 -> 4.3408304
A10: Densité routière (km/km2) | B10: 0 | C10: -0.017919745 | D10: 4.9306272 | E10: 0.53358489 | F10: =INDEX(RESULTATS!$C$2:$C$10,MATCH('enquêtes TIM'!A10,RESULTATS!$B$2:$B$10,0)) -> 17 | G10: =(B10*(F10^2)) + (C10*F10) + D10 -> 4.6259915
A11: Surf. couverte par trottoirs (km2/km2) | B11: 0 | C11: -12.527787 | D11: 4.9387538 | E11: 0.62746941 | F11: =INDEX(RESULTATS!$C$2:$C$10,MATCH('enquêtes TIM'!A11,RESULTATS!$B$2:$B$10,0)) -> 0.015 | G11: =(B11*(F11^2)) + (C11*F11) + D11 -> 4.750837
A12: Typologie courtes distances | B12: 0 | C12: 0.13583671 | D12: 4.1578643 | E12: 0.5158292 | F12: =INDEX(RESULTATS!$C$2:$C$10,MATCH('enquêtes TIM'!A12,RESULTATS!$B$2:$B$10,0)) -> 4 | G12: =(B12*(F12^2)) + (C12*F12) + D12 -> 4.7012112
A13: Classe de desserte TP | B13: 0 | C13: 0.43715831 | D13: 3.675888 | E13: 0.79214905 | F13: =INDEX(Q1:Q4,MATCH(INDEX(RESULTATS!$C$2:$C$10,MATCH('enquêtes TIM'!A13,RESULTATS!$B$2:$B$10,0)),P1:P4,0)) -> 2 | G13: =(B13*(F13^2)) + (C13*F13) + D13 -> 4.5502047

Sheet Calculs_modele
D1: Mean estimation (km TIM pp/j) | E1: Min estimation (km TIM pp/j) | F1: Max estimation (km TIM pp/j) | G1: Weight TIM | H1: Mean estimation (km MD pp/j) | I1: Min estimation (km MD pp/j) | J1: Max estimation (km MD pp/j) | K1: Weight MD | L1: Mean estimation (km TC pp/j) | M1: Min estimation (km TC pp/j) | N1: Max estimation (km TC pp/j) | O1: Weight TC | R1: w tim | S1: w MD | T1: w TC
A2: P_comb_tim | B2: Acc. gravitaire TIM | C2: =INDEX(RESULTATS!$C$2:$C$10,MATCH(B2,RESULTATS!$B$2:$B$10,0)) -> 25676 | D2: {=MAX(INDEX(INDIRECT(ADDRESS(2,2,,,A2)&":"&ADDRESS(1000,2)), MATCH(MIN(ABS(INDIRECT(ADDRESS(2,1,,,A2)&":"&ADDRESS(1000,1)) - C2)),ABS(INDIRECT(ADDRESS(2,1,,,A2)&":"&ADDRESS(1000,1)) - C2),0)),0)} -> 6.0960067 | E2: {=MAX(INDEX(INDIRECT(ADDRESS(2,4,,,A2)&":"&ADDRESS(1000,4)), MATCH(MIN(ABS(INDIRECT(ADDRESS(2,1,,,A2)&":"&ADDRESS(1000,1)) - C2)),ABS(INDIRECT(ADDRESS(2,1,,,A2)&":"&ADDRESS(1000,1)) - C2),0)),0)} -> 4.5278488 | F2: {=MAX(INDEX(INDIRECT(ADDRESS(2,3,,,A2)&":"&ADDRESS(1000,3)), MATCH(MIN(ABS(INDIRECT(ADDRESS(2,1,,,A2)&":"&ADDRESS(1000,1)) - C2)),ABS(INDIRECT(ADDRESS(2,1,,,A2)&":"&ADDRESS(1000,1)) - C2),0)),0)} -> 7.6641646 | G2: =IFERROR((1/(F2-E2)) / $G$12,0) -> 0.89897713 | H2: {=MAX(INDEX(INDIRECT(ADDRESS(2,6,,,A2)&":"&ADDRESS(1000,6)), MATCH(MIN(ABS(INDIRECT(ADDRESS(2,5,,,A2)&":"&ADDRESS(1000,5)) - C2)),ABS(INDIRECT(ADDRESS(2,5,,,A2)&":"&ADDRESS(1000,5)) - C2),0)),0)} -> 1.5789626 | I2: {=MAX(INDEX(INDIRECT(ADDRESS(2,8,,,A2)&":"&ADDRESS(1000,8)), MATCH(MIN(ABS(INDIRECT(ADDRESS(2,5,,,A2)&":"&ADDRESS(1000,5)) - C2)),ABS(INDIRECT(ADDRESS(2,5,,,A2)&":"&ADDRESS(1000,5)) - C2),0)),0)} -> 1.2423915 | J2: {=MAX(INDEX(INDIRECT(ADDRESS(2,7,,,A2)&":"&ADDRESS(1000,7)), MATCH(MIN(ABS(INDIRECT(ADDRESS(2,5,,,A2)&":"&ADDRESS(1000,5)) - C2)),ABS(INDIRECT(ADDRESS(2,5,,,A2)&":"&ADDRESS(1000,5)) - C2),0)),0)} -> 1.9155337 | K2: =IFERROR((1/(J2-I2))/$K$12,0) -> 1 | L2: {=MAX(INDEX(INDIRECT(ADDRESS(2,10,,,A2)&":"&ADDRESS(1000,10)), MATCH(MIN(ABS(INDIRECT(ADDRESS(2,9,,,A2)&":"&ADDRESS(1000,9)) - C2)),ABS(INDIRECT(ADDRESS(2,9,,,A2)&":"&ADDRESS(1000,9)) - C2),0)),0) - (D2+H2)} -> 5.1264939 | M2: {=MIN( MAX(INDEX(INDIRECT(ADDRESS(2,12,,,A2)&":"&ADDRESS(1000,12)), MATCH(MIN(ABS(INDIRECT(ADDRESS(2,9,,,A2)&":"&ADDRESS(1000,9)) - C2)),ABS(INDIRECT(ADDRESS(2,9,,,A2)&":"&ADDRESS(1000,9)) - C2),0)),0) - (E2+I2), MAX(INDEX(INDIRECT(ADDRESS(2,11,,,A2)&":"&ADDRESS(1000,11)), MATCH(MIN(ABS(INDIRECT(ADDRESS(2,9,,,A2)&":"&ADDRESS(1000,9)) - C2)),ABS(INDIRECT(ADDRESS(2,9,,,A2)&":"&ADDRESS(1000,9)) - C2),0)),0) - (F2+J2) )} -> 4.767386 | N2: {=MAX( MAX(INDEX(INDIRECT(ADDRESS(2,12,,,A2)&":"&ADDRESS(1000,12)), MATCH(MIN(ABS(INDIRECT(ADDRESS(2,9,,,A2)&":"&ADDRESS(1000,9)) - C2)),ABS(INDIRECT(ADDRESS(2,9,,,A2)&":"&ADDRESS(1000,9)) - C2),0)),0) - (E2+I2), MAX(INDEX(INDIRECT(ADDRESS(2,11,,,A2)&":"&ADDRESS(1000,11)), MATCH(MIN(ABS(INDIRECT(ADDRESS(2,9,,,A2)&":"&ADDRESS(1000,9)) - C2)),ABS(INDIRECT(ADDRESS(2,9,,,A2)&":"&ADDRESS(1000,9)) - C2),0)),0) - (F2+J2) )} -> 5.4856019 | O2: =IFERROR((1/(N2-M2)) / $O$12,0) -> 0.019139622 | R2: =IF(C2=-99,0,1/(F2-E2)) -> 0.31884544 | S2: =IF(C2=-99,0,1/(J2-I2)) -> 1.4855702 | T2: =IF(C2=-99,0,1/(N2-M2)) -> 1.392339
A3: P_comb_tc | B3: Acc. gravitaire TP | C3: =INDEX(RESULTATS!$C$2:$C$10,MATCH(B3,RESULTATS!$B$2:$B$10,0)) -> 13868 | D3: {=MAX(INDEX(INDIRECT(ADDRESS(2,2,,,A3)&":"&ADDRESS(1000,2)), MATCH(MIN(ABS(INDIRECT(ADDRESS(2,1,,,A3)&":"&ADDRESS(1000,1)) - C3)),ABS(INDIRECT(ADDRESS(2,1,,,A3)&":"&ADDRESS(1000,1)) - C3),0)),0)} -> 6.0589276 | E3: {=MAX(INDEX(INDIRECT(ADDRESS(2,4,,,A3)&":"&ADDRESS(1000,4)), MATCH(MIN(ABS(INDIRECT(ADDRESS(2,1,,,A3)&":"&ADDRESS(1000,1)) - C3)),ABS(INDIRECT(ADDRESS(2,1,,,A3)&":"&ADDRESS(1000,1)) - C3),0)),0)} -> 0.91714396 | F3: {=MAX(INDEX(INDIRECT(ADDRESS(2,3,,,A3)&":"&ADDRESS(1000,3)), MATCH(MIN(ABS(INDIRECT(ADDRESS(2,1,,,A3)&":"&ADDRESS(1000,1)) - C3)),ABS(INDIRECT(ADDRESS(2,1,,,A3)&":"&ADDRESS(1000,1)) - C3),0)),0)} -> 11.200711 | G3: =IFERROR((1/(F3-E3)) / $G$12,0) -> 0.27417297 | H3: {=MAX(INDEX(INDIRECT(ADDRESS(2,6,,,A3)&":"&ADDRESS(1000,6)), MATCH(MIN(ABS(INDIRECT(ADDRESS(2,5,,,A3)&":"&ADDRESS(1000,5)) - C3)),ABS(INDIRECT(ADDRESS(2,5,,,A3)&":"&ADDRESS(1000,5)) - C3),0)),0)} -> 1.3440715 | I3: {=MAX(INDEX(INDIRECT(ADDRESS(2,8,,,A3)&":"&ADDRESS(1000,8)), MATCH(MIN(ABS(INDIRECT(ADDRESS(2,5,,,A3)&":"&ADDRESS(1000,5)) - C3)),ABS(INDIRECT(ADDRESS(2,5,,,A3)&":"&ADDRESS(1000,5)) - C3),0)),0)} -> 0.66093966 | J3: {=MAX(INDEX(INDIRECT(ADDRESS(2,7,,,A3)&":"&ADDRESS(1000,7)), MATCH(MIN(ABS(INDIRECT(ADDRESS(2,5,,,A3)&":"&ADDRESS(1000,5)) - C3)),ABS(INDIRECT(ADDRESS(2,5,,,A3)&":"&ADDRESS(1000,5)) - C3),0)),0)} -> 2.0272034 | K3: =IFERROR((1/(J3-I3))/$K$12,0) -> 0.49268834 | L3: {=MAX(INDEX(INDIRECT(ADDRESS(2,10,,,A3)&":"&ADDRESS(1000,10)), MATCH(MIN(ABS(INDIRECT(ADDRESS(2,9,,,A3)&":"&ADDRESS(1000,9)) - C3)),ABS(INDIRECT(ADDRESS(2,9,,,A3)&":"&ADDRESS(1000,9)) - C3),0)),0) - (D3+H3)} -> 4.8260354 | M3: {=MIN( MAX(INDEX(INDIRECT(ADDRESS(2,12,,,A3)&":"&ADDRESS(1000,12)), MATCH(MIN(ABS(INDIRECT(ADDRESS(2,9,,,A3)&":"&ADDRESS(1000,9)) - C3)),ABS(INDIRECT(ADDRESS(2,9,,,A3)&":"&ADDRESS(1000,9)) - C3),0)),0) - (E3+I3), MAX(INDEX(INDIRECT(ADDRESS(2,11,,,A3)&":"&ADDRESS(1000,11)), MATCH(MIN(ABS(INDIRECT(ADDRESS(2,9,,,A3)&":"&ADDRESS(1000,9)) - C3)),ABS(INDIRECT(ADDRESS(2,9,,,A3)&":"&ADDRESS(1000,9)) - C3),0)),0) - (F3+J3) )} -> 4.8188755 | N3: {=MAX( MAX(INDEX(INDIRECT(ADDRESS(2,12,,,A3)&":"&ADDRESS(1000,12)), MATCH(MIN(ABS(INDIRECT(ADDRESS(2,9,,,A3)&":"&ADDRESS(1000,9)) - C3)),ABS(INDIRECT(ADDRESS(2,9,,,A3)&":"&ADDRESS(1000,9)) - C3),0)),0) - (E3+I3), MAX(INDEX(INDIRECT(ADDRESS(2,11,,,A3)&":"&ADDRESS(1000,11)), MATCH(MIN(ABS(INDIRECT(ADDRESS(2,9,,,A3)&":"&ADDRESS(1000,9)) - C3)),ABS(INDIRECT(ADDRESS(2,9,,,A3)&":"&ADDRESS(1000,9)) - C3),0)),0) - (F3+J3) )} -> 4.8331954 | O3: =IFERROR((1/(N3-M3)) / $O$12,0) -> 0.95994752 | R3: =IF(C3=-99,0,1/(F3-E3)) -> 0.097242521 | S3: =IF(C3=-99,0,1/(J3-I3)) -> 0.7319231 | T3: =IF(C3=-99,0,1/(N3-M3)) -> 69.832745
A4: B_DENS | B4: Dens. bâtiments (bât/m2) | C4: =INDEX(RESULTATS!$C$2:$C$10,MATCH(B4,RESULTATS!$B$2:$B$10,0)) -> 0.08 | D4: {=MAX(INDEX(INDIRECT(ADDRESS(2,2,,,A4)&":"&ADDRESS(1000,2)), MATCH(MIN(ABS(INDIRECT(ADDRESS(2,1,,,A4)&":"&ADDRESS(1000,1)) - C4)),ABS(INDIRECT(ADDRESS(2,1,,,A4)&":"&ADDRESS(1000,1)) - C4),0)),0)} -> 9.0725103 | E4: {=MAX(INDEX(INDIRECT(ADDRESS(2,4,,,A4)&":"&ADDRESS(1000,4)), MATCH(MIN(ABS(INDIRECT(ADDRESS(2,1,,,A4)&":"&ADDRESS(1000,1)) - C4)),ABS(INDIRECT(ADDRESS(2,1,,,A4)&":"&ADDRESS(1000,1)) - C4),0)),0)} -> 5.0518212 | F4: {=MAX(INDEX(INDIRECT(ADDRESS(2,3,,,A4)&":"&ADDRESS(1000,3)), MATCH(MIN(ABS(INDIRECT(ADDRESS(2,1,,,A4)&":"&ADDRESS(1000,1)) - C4)),ABS(INDIRECT(ADDRESS(2,1,,,A4)&":"&ADDRESS(1000,1)) - C4),0)),0)} -> 13.093199 | G4: =IFERROR((1/(F4-E4)) / $G$12,0) -> 0.35062102 | H4: {=MAX(INDEX(INDIRECT(ADDRESS(2,6,,,A4)&":"&ADDRESS(1000,6)), MATCH(MIN(ABS(INDIRECT(ADDRESS(2,5,,,A4)&":"&ADDRESS(1000,5)) - C4)),ABS(INDIRECT(ADDRESS(2,5,,,A4)&":"&ADDRESS(1000,5)) - C4),0)),0)} -> 1.2209542 | I4: {=MAX(INDEX(INDIRECT(ADDRESS(2,8,,,A4)&":"&ADDRESS(1000,8)), MATCH(MIN(ABS(INDIRECT(ADDRESS(2,5,,,A4)&":"&ADDRESS(1000,5)) - C4)),ABS(INDIRECT(ADDRESS(2,5,,,A4)&":"&ADDRESS(1000,5)) - C4),0)),0)} -> 0.42958086 | J4: {=MAX(INDEX(INDIRECT(ADDRESS(2,7,,,A4)&":"&ADDRESS(1000,7)), MATCH(MIN(ABS(INDIRECT(ADDRESS(2,5,,,A4)&":"&ADDRESS(1000,5)) - C4)),ABS(INDIRECT(ADDRESS(2,5,,,A4)&":"&ADDRESS(1000,5)) - C4),0)),0)} -> 2.0123275 | K4: =IFERROR((1/(J4-I4))/$K$12,0) -> 0.42530004 | L4: {=MAX(INDEX(INDIRECT(ADDRESS(2,10,,,A4)&":"&ADDRESS(1000,10)), MATCH(MIN(ABS(INDIRECT(ADDRESS(2,9,,,A4)&":"&ADDRESS(1000,9)) - C4)),ABS(INDIRECT(ADDRESS(2,9,,,A4)&":"&ADDRESS(1000,9)) - C4),0)),0) - (D4+H4)} -> 5.8502011 | M4: {=MIN( MAX(INDEX(INDIRECT(ADDRESS(2,12,,,A4)&":"&ADDRESS(1000,12)), MATCH(MIN(ABS(INDIRECT(ADDRESS(2,9,,,A4)&":"&ADDRESS(1000,9)) - C4)),ABS(INDIRECT(ADDRESS(2,9,,,A4)&":"&ADDRESS(1000,9)) - C4),0)),0) - (E4+I4), MAX(INDEX(INDIRECT(ADDRESS(2,11,,,A4)&":"&ADDRESS(1000,11)), MATCH(MIN(ABS(INDIRECT(ADDRESS(2,9,,,A4)&":"&ADDRESS(1000,9)) - C4)),ABS(INDIRECT(ADDRESS(2,9,,,A4)&":"&ADDRESS(1000,9)) - C4),0)),0) - (F4+J4) )} -> 5.8433279 | N4: {=MAX( MAX(INDEX(INDIRECT(ADDRESS(2,12,,,A4)&":"&ADDRESS(1000,12)), MATCH(MIN(ABS(INDIRECT(ADDRESS(2,9,,,A4)&":"&ADDRESS(1000,9)) - C4)),ABS(INDIRECT(ADDRESS(2,9,,,A4)&":"&ADDRESS(1000,9)) - C4),0)),0) - (E4+I4), MAX(INDEX(INDIRECT(ADDRESS(2,11,,,A4)&":"&ADDRESS(1000,11)), MATCH(MIN(ABS(INDIRECT(ADDRESS(2,9,,,A4)&":"&ADDRESS(1000,9)) - C4)),ABS(INDIRECT(ADDRESS(2,9,,,A4)&":"&ADDRESS(1000,9)) - C4),0)),0) - (F4+J4) )} -> 5.8570743 | O4: =IFERROR((1/(N4-M4)) / $O$12,0) -> 1 | R4: =IF(C4=-99,0,1/(F4-E4)) -> 0.12435679 | S4: =IF(C4=-99,0,1/(J4-I4)) -> 0.63181306 | T4: =IF(C4=-99,0,1/(N4-M4)) -> 72.746419
